<?xml version="1.0" ?>
<!-- =================================================================================== -->
<!-- |    This document was autogenerated by xacro from float_wsg50.xacro              | -->
<!-- |    EDITING THIS FILE BY HAND IS NOT RECOMMENDED                                 | -->
<!-- =================================================================================== -->
<robot name="float_wsg50" xmlns:controller="http://playerstage.sourceforge.net/gazebo/xmlschema/#controller" xmlns:interface="http://playerstage.sourceforge.net/gazebo/xmlschema/#interface" xmlns:sensor="http://playerstage.sourceforge.net/gazebo/xmlschema/#sensor">
  <material name="Black">
    <color rgba="0.0 0.0 0.0 1.0"/>
  </material>
  <material name="Blue">
    <color rgba="0.0 0.0 0.8 1.0"/>
  </material>
  <material name="Green">
    <color rgba="0.0 0.8 0.0 1.0"/>
  </material>
  <material name="Grey">
    <color rgba="0.4 0.4 0.4 1.0"/>
  </material>
  <material name="Orange">
    <color rgba="1.0 0.4235294117647059 0.0392156862745098 1.0"/>
  </material>
  <material name="Brown">
    <color rgba="0.8705882352941177 0.8117647058823529 0.7647058823529411 1.0"/>
  </material>
  <material name="Red">
    <color rgba="0.8 0.0 0.0 1.0"/>
  </material>
  <material name="White">
    <color rgba="1.0 1.0 1.0 1.0"/>
  </material>
  <material name="LightGrey">
    <color rgba="0.7 0.7 0.7 1"/>
  </material>
  <material name="DarkGray">
    <color rgba="0.2 0.2 0.2 1"/>
  </material>
  <material name="DarkDarkGray">
    <color rgba="0.1 0.1 0.1 1"/>
  </material>
  <!-- Make a base link. -->
  <link name="world" type="fixed">
    <inertial>
      <mass value="0"/>
      <inertia ixx="0" ixy="0" ixz="0" iyy="0" iyz="0" izz="0"/>
    </inertial>
  </link>
  <joint name="wsg50_plate_joint" type="fixed">
    <origin rpy="0 0 -1.5708" xyz="0 0 0"/>
    <!-- <origin xyz="0 0 0" rpy="0 0 -1.5708"/> -->
    <parent link="world"/>
    <child link="wsg50_plate"/>
  </joint>
  <!-- GRIPPER PLATE -->
  <link name="wsg50_plate">
    <inertial>
      <mass value="0.0"/>
      <!-- This is not the true mass -->
      <origin xyz="0 0 0"/>
      <inertia ixx="1.0" ixy="0.0" ixz="0.0" iyy="1.0" iyz="0.0" izz="1.0"/>
      <!-- This are not the true inertia -->
    </inertial>
    <visual>
      <origin rpy="0 0 0" xyz="0.0 0 0"/>
      <geometry>
        <mesh filename="package://meshes/wsg50/wsg50_plate.stl" scale="1 1 1"/>
        <!--box size="0.146 0.05 0.0735"/-->
      </geometry>
      <material name="grey">
        <color rgba="0.5 0.5 0.5 1"/>
      </material>
    </visual>
    <collision>
      <origin rpy="0 0 0" xyz="0.0 0 0"/>
      <geometry>
        <!--box size="0.146 0.05 0.0735"/-->
        <mesh filename="package://meshes/wsg50/wsg50_plate.stl" scale="1 1 1"/>
      </geometry>
    </collision>
  </link>
  <gazebo reference="wsg50_plate">
    <material>Gazebo/Grey</material>
    <turnGravityOff>false</turnGravityOff>
  </gazebo>
  <!-- GRIPPER -->
  <joint name="wsg50_anterior_gripper_joint" type="fixed">
    <origin rpy="0 0 0" xyz="0 0 0.01"/>
    <!-- <origin xyz="0 0 0" rpy="0 0 -1.5708"/> -->
    <parent link="wsg50_plate"/>
    <child link="wsg50_base_link"/>
  </joint>
  <!-- BASE LINK -->
  <link name="wsg50_base_link">
    <inertial>
      <mass value="1.48"/>
      <origin xyz="0.00363 -0.00829 0.015"/>
      <!--inertia ixx="1.0" ixy="0.0" ixz="0.0"
                    iyy="100.0" iyz="0.0"
                    izz="1.0" /-->
      <inertia ixx="0.0" ixy="0.0" ixz="0.0" iyy="0.0" iyz="0.0" izz="0.0"/>
    </inertial>
    <visual>
      <origin rpy="0 0 0" xyz="0.0 0 0"/>
      <geometry>
        <mesh filename="package://meshes/wsg50/WSG50_110.stl" scale="1 1 1"/>
        <!--box size="0.146 0.05 0.0735"/-->
      </geometry>
      <material name="grey">
        <color rgba="0.5 0.5 0.5 1"/>
      </material>
    </visual>
    <collision>
      <origin rpy="0 0 0" xyz="0.0 0 0"/>
      <geometry>
        <!--box size="0.146 0.05 0.0735"/-->
        <mesh filename="package://meshes/wsg50/WSG50_110.stl" scale="1 1 1"/>
      </geometry>
    </collision>
  </link>
  <gazebo reference="wsg50_base_link">
    <material>Gazebo/Grey</material>
    <turnGravityOff>false</turnGravityOff>
  </gazebo>
  <joint name="wsg50_center_joint" type="fixed">
    <origin rpy="0 0 0" xyz="0 0 0.023"/>
    <!--origin xyz="-0.0067 0 0.049" rpy="0 0 0" /-->
    <parent link="wsg50_base_link"/>
    <child link="wsg50_center"/>
  </joint>
  <link name="wsg50_center">
    <inertial>
      <mass value="0"/>
      <inertia ixx="0" ixy="0" ixz="0" iyy="0" iyz="0" izz="0"/>
    </inertial>
  </link>
  <!-- GRIPPER LEFT -->
  <joint name="wsg50_finger_left_joint" type="prismatic">
    <limit effort="1.0" lower="-0.055" upper="-0.03" velocity="1.0"/>
    <origin rpy="0 0 0" xyz="0 0 0"/>
    <!--origin xyz="-0.0067 0 0.049" rpy="0 0 0" /-->
    <parent link="wsg50_base_link"/>
    <child link="wsg50_gripper_left"/>
    <dynamics damping="100" friction="100"/>
    <axis xyz="1 0 0"/>
  </joint>
  <transmission name="wsg50_base_trans_left">
    <type>transmission_interface/SimpleTransmission</type>
    <actuator name="wsg50_base_motor_left">
      <mechanicalReduction>1</mechanicalReduction>
    </actuator>
    <joint name="wsg50_finger_left_joint">
      <hardwareInterface>hardware_interface/PositionJointInterface</hardwareInterface>
    </joint>
  </transmission>
  <link name="wsg50_gripper_left">
    <inertial>
      <mass value="0.1"/>
      <origin xyz="0 0 0"/>
      <inertia ixx="1.0" ixy="0.0" ixz="0.0" iyy="1.0" iyz="0.0" izz="1.0"/>
    </inertial>
    <visual>
      <origin rpy="0 0 0" xyz="0.0 0 0"/>
      <geometry>
        <mesh filename="package://meshes/wsg50/GUIDE_WSG50_110.stl" scale="0.001 0.001 0.001"/>
        <!--box size="0.0175 0.03 0.024"/-->
      </geometry>
      <material name="black">
        <color rgba="0 0 0 1"/>
      </material>
    </visual>
    <collision>
      <origin rpy="0 0 0" xyz="0 0 0"/>
      <geometry>
        <!--box size="0.0175 0.03 0.024"/-->
        <mesh filename="package://meshes/wsg50/GUIDE_WSG50_110.stl" scale="0.001 0.001 0.001"/>
      </geometry>
    </collision>
    <contact_coefficients kd="1.0" kp="1000.0" mu="0"/>
  </link>
  <gazebo reference="wsg50_gripper_left">
    <material>Gazebo/Blue</material>
    <turnGravityOff>false</turnGravityOff>
  </gazebo>
  <!-- GRIPPER RIGHT -->
  <joint name="wsg50_finger_right_joint" type="prismatic">
    <limit effort="1.0" lower="0.03" upper="0.055" velocity="1.0"/>
    <origin rpy="0 0 3.14159" xyz="0 0 0"/>
    <parent link="wsg50_base_link"/>
    <child link="wsg50_gripper_right"/>
    <axis xyz="-1 0 0"/>
    <dynamics damping="100" friction="100"/>
  </joint>
  <transmission name="wsg50_base_trans_right">
    <type>transmission_interface/SimpleTransmission</type>
    <actuator name="wsg50_base_motor_right">
      <mechanicalReduction>1</mechanicalReduction>
    </actuator>
    <joint name="wsg50_finger_right_joint">
      <hardwareInterface>hardware_interface/PositionJointInterface</hardwareInterface>
    </joint>
  </transmission>
  <link name="wsg50_gripper_right">
    <inertial>
      <mass value="0.1"/>
      <origin xyz="0 0 0"/>
      <inertia ixx="1.0" ixy="0.0" ixz="0.0" iyy="1.0" iyz="0.0" izz="1.0"/>
    </inertial>
    <visual>
      <origin rpy="0 0 0" xyz="0.0 0 0"/>
      <geometry>
        <mesh filename="package://meshes/wsg50/GUIDE_WSG50_110.stl" scale="0.001 0.001 0.001"/>
        <!--box size="0.0175 0.03 0.024"/-->
      </geometry>
      <material name="black">
        <color rgba="0 0 0 1"/>
      </material>
    </visual>
    <collision>
      <origin rpy="0 0 0" xyz="0 0 0"/>
      <geometry>
        <!--box size="0.0175 0.03 0.024"/-->
        <mesh filename="package://meshes/wsg50/GUIDE_WSG50_110.stl" scale="0.001 0.001 0.001"/>
      </geometry>
    </collision>
    <contact_coefficients kd="1.0" kp="1000.0" mu="0"/>
  </link>
  <gazebo reference="gripper_right">
    <material>Gazebo/White</material>
    <turnGravityOff>false</turnGravityOff>
  </gazebo>
  <!--  ~~~~~~~~~~~~~~~~~~~~~~~~~~~~~~~~~~~~~~~~~~~~~~~~~~~~~~~~~~~~~~~~~~~~~~~~~~~~~~~~~~~~~~~      -->
  <!--  ~~~~~~~~ FINGERS ~~~~~~~~~~~~~~~~~~~~~~~~~~~~~~~~~~~~~~~~~~~~~~~~~~~~~~~~~~~~~~~~~~~~~~      -->
  <!--  ~~~~~~~~~~~~~~~~~~~~~~~~~~~~~~~~~~~~~~~~~~~~~~~~~~~~~~~~~~~~~~~~~~~~~~~~~~~~~~~~~~~~~~~      -->
  <!-- Flipped Bubbles -->
  <!-- LEFT FINGER -->
  <joint name="wsg50_guide_joint_finger_left" type="fixed">
    <origin rpy="0 0 0" xyz="-0.009 0 .089"/>
    <parent link="wsg50_gripper_left"/>
    <child link="wsg50_finger_left"/>
    <dynamics damping="100" friction="100"/>
    <axis xyz="1 0 0"/>
    <limit effort="100" velocity="100"/>
  </joint>
  <link name="wsg50_finger_left">
    <inertial>
      <mass value="0.1"/>
      <origin xyz="0 0 0"/>
      <inertia ixx="1.0" ixy="0.0" ixz="0.0" iyy="1.0" iyz="0.0" izz="1.0"/>
    </inertial>
    <visual>
      <origin rpy="0 -1.8661 0" xyz="-0.0252755 0 0.0434163"/>
      <geometry>
        <mesh filename="package://meshes/bubbles/collision/bubble_flipped_inflated.stl" scale="0.001 0.001 0.001"/>
      </geometry>
      <material name="pastel">
        <color rgba="0.8588 0.5255 0.6588 1"/>
      </material>
    </visual>
    <collision>
      <origin rpy="0 -1.8661 0" xyz="-0.0252755 0 0.0434163"/>
      <geometry>
        <mesh filename="package://meshes/bubbles/collision/bubble_flipped_inflated.stl" scale="0.001 0.001 0.001"/>
      </geometry>
    </collision>
    <contact_coefficients kd="1.0" kp="1000.0" mu="0"/>
  </link>
  <!-- LEFT CAMERA FRAME -->
  <joint name="wsg50_left_bubble_camera_frame_fake_joint" type="fixed">
    <origin rpy="0 -1.8661 0" xyz="-0.0252755 0 0.0434163"/>
    <parent link="wsg50_finger_left"/>
    <child link="left_bubble_camera_frame"/>
  </joint>
  <link name="left_bubble_camera_frame">
    <inertial>
      <mass value="0.0"/>
      <origin xyz="0 0 0"/>
      <inertia ixx="0.0" ixy="0.0" ixz="0.0" iyy="0.0" iyz="0.0" izz="0.0"/>
    </inertial>
  </link>
  <!-- RIGHT FINGER -->
  <joint name="wsg50_guide_joint_finger_right" type="fixed">
    <origin rpy="0 0 0" xyz="-0.009 0 .089"/>
    <parent link="wsg50_gripper_right"/>
    <child link="wsg50_finger_right"/>
    <dynamics damping="100" friction="100"/>
    <axis xyz="1 0 0"/>
    <limit effort="100" velocity="100"/>
  </joint>
  <link name="wsg50_finger_right">
    <inertial>
      <mass value="0.1"/>
      <origin xyz="0 0 0"/>
      <inertia ixx="1.0" ixy="0.0" ixz="0.0" iyy="1.0" iyz="0.0" izz="1.0"/>
    </inertial>
    <visual>
      <origin rpy="0 -1.8661 0" xyz="-0.0252755 0 0.0434163"/>
      <geometry>
        <mesh filename="package://meshes/bubbles/collision/bubble_flipped_inflated.stl" scale="0.001 0.001 0.001"/>
      </geometry>
      <material name="pastel">
        <color rgba="0.8588 0.5255 0.6588 1"/>
      </material>
    </visual>
    <collision>
      <origin rpy="0 -1.8661 0" xyz="-0.0252755 0 0.0434163"/>
      <geometry>
        <mesh filename="package://meshes/bubbles/visual/bubble_flipped_inflated.stl" scale="0.001 0.001 0.001"/>
      </geometry>
    </collision>
    <contact_coefficients kd="1.0" kp="1000.0" mu="0"/>
    <contact_coefficients kd="1.0" kp="1000.0" mu="0"/>
  </link>
  <!-- RIGHT CAMERA FRAME -->
  <joint name="wsg50_right_bubble_camera_frame_fake_joint" type="fixed">
    <origin rpy="0 -1.8661 0" xyz="-0.0252755 0 0.0434163"/>
    <parent link="wsg50_finger_right"/>
    <child link="right_bubble_camera_frame"/>
  </joint>
  <link name="right_bubble_camera_frame">
    <inertial>
      <mass value="0.0"/>
      <origin xyz="0 0 0"/>
      <inertia ixx="0.0" ixy="0.0" ixz="0.0" iyy="0.0" iyz="0.0" izz="0.0"/>
    </inertial>
  </link>
  <!--  ==================================  END OF FINGER SELECTION  ==================================  -->
  <gazebo reference="wsg50_finger_left">
    <material>Gazebo/Blue</material>
    <turnGravityOff>false</turnGravityOff>
  </gazebo>
  <gazebo reference="wsg50_finger_right">
    <material>Gazebo/White</material>
    <turnGravityOff>false</turnGravityOff>
  </gazebo>
  <!-- GRASP FRAME -->
  <joint name="wsg50_grasp_frame_fake_joint" type="fixed">
    <!-- <origin xyz="0 0 0" rpy="0 0 -1.5708"/> -->
    <parent link="wsg50_base_link"/>
    <child link="grasp_frame"/>
  </joint>
  <link name="grasp_frame">
    <inertial>
      <mass value="0.0"/>
      <origin xyz="0 0 0"/>
      <inertia ixx="0.0" ixy="0.0" ixz="0.0" iyy="0.0" iyz="0.0" izz="0.0"/>
    </inertial>
  </link>
  <!-- RIGHT FINGER TIP FRAME -->
  <joint name="wsg50_right_finger_tip_fake_joint" type="fixed">
    <origin rpy="0 0 3.14159" xyz="0 0 0.121"/>
    <!-- May be worth considering the parameter finger_tip-->
    <!-- <origin xyz="0 0 0" rpy="0 0 -1.5708"/> -->
    <parent link="wsg50_finger_right"/>
    <child link="wsg50_finger_right_tip"/>
  </joint>
  <link name="wsg50_finger_right_tip">
    <inertial>
      <mass value="0.0"/>
      <origin xyz="0 0 0"/>
      <inertia ixx="0.0" ixy="0.0" ixz="0.0" iyy="0.0" iyz="0.0" izz="0.0"/>
    </inertial>
  </link>
  <!-- LEFT FINGER TIP FRAME -->
  <joint name="wsg50_left_finger_tip_fake_joint" type="fixed">
    <origin rpy="0 0 0" xyz="0 0 0.121"/>
    <!-- May be worth considering the parameter finger_tip-->
    <!-- <origin xyz="0 0 0" rpy="0 0 -1.5708"/> -->
    <parent link="wsg50_finger_left"/>
    <child link="wsg50_finger_left_tip"/>
  </joint>
  <link name="wsg50_finger_left_tip">
    <inertial>
      <mass value="0.0"/>
      <origin xyz="0 0 0"/>
      <inertia ixx="0.0" ixy="0.0" ixz="0.0" iyy="0.0" iyz="0.0" izz="0.0"/>
    </inertial>
  </link>
</robot>

